<?xml version="1.0" encoding="UTF-8"?>
<robot name="simple_2dof" xmlns:urdf="http://www.ros.org/wiki/urdf">
    <link name="base_link">
        <visual>
            <geometry>
                <box size="0.1 0.1 0.5"/>
            </geometry>
        </visual>
        <inertial>
            <origin xyz="0 0 1" rpy="0 0 0"/>
            <mass value="1"/>
            <inertia
                ixx="1.0" ixy="0.0" ixz="0.0"
                iyy="1.0" iyz="0.0"
                izz="1.0"/>
        </inertial>
    </link>

    <link name="right_leg">
        <visual>
            <geometry>
                <box size="0.1 0.1 0.5"/>
            </geometry>
        </visual>
        <inertial>
            <origin xyz="0 0 1" rpy="0 0 0"/>
            <mass value="1"/>
            <inertia
                ixx="1.0" ixy="0.0" ixz="0.0"
                iyy="1.0" iyz="0.0"
                izz="1.0"/>
        </inertial>
    </link>

    <joint name="base_to_right_leg" type="continuous">
        <parent link="base_link"/>
        <child link="right_leg"/>
        <origin xyz="0.0 0.05 0.225" rpy="0 0 0"/>
        <axis xyz="0 1 0"/>
    </joint>
</robot>